[2024-06-18T06:34:23.483+0000] {local_task_job_runner.py:120} INFO - ::group::Pre task execution logs
[2024-06-18T06:34:23.572+0000] {taskinstance.py:2076} INFO - Dependencies all met for dep_context=non-requeueable deps ti=<TaskInstance: testing.fetching_data manual__2024-06-18T06:34:21.977655+00:00 [queued]>
[2024-06-18T06:34:23.580+0000] {taskinstance.py:2076} INFO - Dependencies all met for dep_context=requeueable deps ti=<TaskInstance: testing.fetching_data manual__2024-06-18T06:34:21.977655+00:00 [queued]>
[2024-06-18T06:34:23.580+0000] {taskinstance.py:2306} INFO - Starting attempt 1 of 1
[2024-06-18T06:34:23.591+0000] {taskinstance.py:2330} INFO - Executing <Task(PythonOperator): fetching_data> on 2024-06-18 06:34:21.977655+00:00
[2024-06-18T06:34:23.596+0000] {standard_task_runner.py:90} INFO - Running: ['***', 'tasks', 'run', 'testing', 'fetching_data', 'manual__2024-06-18T06:34:21.977655+00:00', '--job-id', '37', '--raw', '--subdir', 'DAGS_FOLDER/readDataFromDB.py', '--cfg-path', '/tmp/tmpezsc0wl5']
[2024-06-18T06:34:23.598+0000] {standard_task_runner.py:91} INFO - Job 37: Subtask fetching_data
[2024-06-18T06:34:23.600+0000] {logging_mixin.py:188} WARNING - /home/***/.local/lib/python3.12/site-packages/***/task/task_runner/standard_task_runner.py:61 DeprecationWarning: This process (pid=8061) is multi-threaded, use of fork() may lead to deadlocks in the child.
[2024-06-18T06:34:23.600+0000] {standard_task_runner.py:63} INFO - Started process 8062 to run task
[2024-06-18T06:34:23.653+0000] {task_command.py:426} INFO - Running <TaskInstance: testing.fetching_data manual__2024-06-18T06:34:21.977655+00:00 [running]> on host 39ad15fd710d
[2024-06-18T06:34:23.746+0000] {taskinstance.py:2648} INFO - Exporting env vars: AIRFLOW_CTX_DAG_OWNER='***' AIRFLOW_CTX_DAG_ID='testing' AIRFLOW_CTX_TASK_ID='fetching_data' AIRFLOW_CTX_EXECUTION_DATE='2024-06-18T06:34:21.977655+00:00' AIRFLOW_CTX_TRY_NUMBER='1' AIRFLOW_CTX_DAG_RUN_ID='manual__2024-06-18T06:34:21.977655+00:00'
[2024-06-18T06:34:23.747+0000] {taskinstance.py:430} INFO - ::endgroup::
[2024-06-18T06:34:23.774+0000] {readDataFromDB.py:17} INFO - Establising connection in connect_to_db method...
[2024-06-18T06:34:23.774+0000] {readDataFromDB.py:47} ERROR - Something went wrong. -->>  invalid dsn: invalid connection option "databse"

[2024-06-18T06:34:23.774+0000] {python.py:237} INFO - Done. Returned value was: None
[2024-06-18T06:34:23.775+0000] {taskinstance.py:441} INFO - ::group::Post task execution logs
[2024-06-18T06:34:23.785+0000] {taskinstance.py:1206} INFO - Marking task as SUCCESS. dag_id=testing, task_id=fetching_data, run_id=manual__2024-06-18T06:34:21.977655+00:00, execution_date=20240618T063421, start_date=20240618T063423, end_date=20240618T063423
[2024-06-18T06:34:23.818+0000] {local_task_job_runner.py:240} INFO - Task exited with return code 0
[2024-06-18T06:34:23.836+0000] {taskinstance.py:3498} INFO - 0 downstream tasks scheduled from follow-on schedule check
[2024-06-18T06:34:23.837+0000] {local_task_job_runner.py:222} INFO - ::endgroup::
