[2024-06-16T07:28:15.652+0000] {local_task_job_runner.py:120} INFO - ::group::Pre task execution logs
[2024-06-16T07:28:15.736+0000] {taskinstance.py:2076} INFO - Dependencies all met for dep_context=non-requeueable deps ti=<TaskInstance: status_dag.read_state manual__2024-06-16T07:28:13.770967+00:00 [queued]>
[2024-06-16T07:28:15.777+0000] {taskinstance.py:2076} INFO - Dependencies all met for dep_context=requeueable deps ti=<TaskInstance: status_dag.read_state manual__2024-06-16T07:28:13.770967+00:00 [queued]>
[2024-06-16T07:28:15.777+0000] {taskinstance.py:2306} INFO - Starting attempt 1 of 1
[2024-06-16T07:28:15.824+0000] {taskinstance.py:2330} INFO - Executing <Task(PythonOperator): read_state> on 2024-06-16 07:28:13.770967+00:00
[2024-06-16T07:28:15.833+0000] {standard_task_runner.py:90} INFO - Running: ['***', 'tasks', 'run', 'status_dag', 'read_state', 'manual__2024-06-16T07:28:13.770967+00:00', '--job-id', '13', '--raw', '--subdir', 'DAGS_FOLDER/firstDAG.py', '--cfg-path', '/tmp/tmp32u_uj64']
[2024-06-16T07:28:15.835+0000] {standard_task_runner.py:91} INFO - Job 13: Subtask read_state
[2024-06-16T07:28:15.851+0000] {logging_mixin.py:188} WARNING - /home/***/.local/lib/python3.12/site-packages/***/task/task_runner/standard_task_runner.py:61 DeprecationWarning: This process (pid=299) is multi-threaded, use of fork() may lead to deadlocks in the child.
[2024-06-16T07:28:15.852+0000] {standard_task_runner.py:63} INFO - Started process 300 to run task
[2024-06-16T07:28:15.953+0000] {task_command.py:426} INFO - Running <TaskInstance: status_dag.read_state manual__2024-06-16T07:28:13.770967+00:00 [running]> on host 15cc12e76742
[2024-06-16T07:28:16.081+0000] {taskinstance.py:2648} INFO - Exporting env vars: AIRFLOW_CTX_DAG_OWNER='ariflow' AIRFLOW_CTX_DAG_ID='status_dag' AIRFLOW_CTX_TASK_ID='read_state' AIRFLOW_CTX_EXECUTION_DATE='2024-06-16T07:28:13.770967+00:00' AIRFLOW_CTX_TRY_NUMBER='1' AIRFLOW_CTX_DAG_RUN_ID='manual__2024-06-16T07:28:13.770967+00:00'
[2024-06-16T07:28:16.081+0000] {taskinstance.py:430} INFO - ::endgroup::
[2024-06-16T07:28:16.097+0000] {taskinstance.py:441} INFO - ::group::Post task execution logs
[2024-06-16T07:28:16.097+0000] {taskinstance.py:2905} ERROR - Task failed with exception
Traceback (most recent call last):
  File "/home/airflow/.local/lib/python3.12/site-packages/airflow/models/taskinstance.py", line 465, in _execute_task
    result = _execute_callable(context=context, **execute_callable_kwargs)
             ^^^^^^^^^^^^^^^^^^^^^^^^^^^^^^^^^^^^^^^^^^^^^^^^^^^^^^^^^^^^^
  File "/home/airflow/.local/lib/python3.12/site-packages/airflow/models/taskinstance.py", line 432, in _execute_callable
    return execute_callable(context=context, **execute_callable_kwargs)
           ^^^^^^^^^^^^^^^^^^^^^^^^^^^^^^^^^^^^^^^^^^^^^^^^^^^^^^^^^^^^
  File "/home/airflow/.local/lib/python3.12/site-packages/airflow/models/baseoperator.py", line 400, in wrapper
    return func(self, *args, **kwargs)
           ^^^^^^^^^^^^^^^^^^^^^^^^^^^
  File "/home/airflow/.local/lib/python3.12/site-packages/airflow/operators/python.py", line 235, in execute
    return_value = self.execute_callable()
                   ^^^^^^^^^^^^^^^^^^^^^^^
  File "/home/airflow/.local/lib/python3.12/site-packages/airflow/operators/python.py", line 252, in execute_callable
    return self.python_callable(*self.op_args, **self.op_kwargs)
           ^^^^^^^^^^^^^^^^^^^^^^^^^^^^^^^^^^^^^^^^^^^^^^^^^^^^^
  File "/opt/airflow/dags/firstDAG.py", line 11, in pull_and_log
    state = kwargs['ti'].xcom_pull(value='state', task_ids='get_state')
            ^^^^^^^^^^^^^^^^^^^^^^^^^^^^^^^^^^^^^^^^^^^^^^^^^^^^^^^^^^^
  File "/home/airflow/.local/lib/python3.12/site-packages/airflow/utils/session.py", line 79, in wrapper
    return func(*args, session=session, **kwargs)
           ^^^^^^^^^^^^^^^^^^^^^^^^^^^^^^^^^^^^^^
TypeError: TaskInstance.xcom_pull() got an unexpected keyword argument 'value'
[2024-06-16T07:28:16.109+0000] {taskinstance.py:1206} INFO - Marking task as FAILED. dag_id=status_dag, task_id=read_state, run_id=manual__2024-06-16T07:28:13.770967+00:00, execution_date=20240616T072813, start_date=20240616T072815, end_date=20240616T072816
[2024-06-16T07:28:16.122+0000] {standard_task_runner.py:110} ERROR - Failed to execute job 13 for task read_state (TaskInstance.xcom_pull() got an unexpected keyword argument 'value'; 300)
[2024-06-16T07:28:16.135+0000] {local_task_job_runner.py:240} INFO - Task exited with return code 1
[2024-06-16T07:28:16.166+0000] {taskinstance.py:3498} INFO - 0 downstream tasks scheduled from follow-on schedule check
[2024-06-16T07:28:16.168+0000] {local_task_job_runner.py:222} INFO - ::endgroup::
